Workbook

Sheet Synthèse
B2: B Â T I - S U D · G R O U P E A R T I S A N A L
B3: Rapport de pilotage — synthèse | K3: Bâti-Sud
B4: Niveau strategique · exercice 2025-2026 (01/07/2025 → 30/06/2026)
B7: CHIFFRE D'AFFAIRES PAR TECHNICIEN | E7: TAUX DE MARGE BRUTE | H7: CONCENTRATION DU CHIFFRE D'AFFAIRES | K7: DSO — DÉLAI MOYEN D'ENCAISSEMENT
B8: =IFERROR(SUMIFS(Interventions!$R$2:$R$1106,Interventions!$C$2:$C$1106,">="&Paramètres!$C$9,Interventions!$C$2:$C$1106,"<="&Paramètres!$C$10)/SUMIFS(Interventions!$V$2:$V$1106,Interventions!$C$2:$C$1106,">="&Paramètres!$C$9,Interventions!$C$2:$C$1106,"<="&Paramètres!$C$10),"") | E8: =IFERROR(SUMIFS(Factures!$V$2:$V$1085,Factures!$F$2:$F$1085,">="&Paramètres!$C$9,Factures!$F$2:$F$1085,"<="&Paramètres!$C$10)/SUMIFS(Factures!$K$2:$K$1085,Factures!$F$2:$F$1085,">="&Paramètres!$C$9,Factures!$F$2:$F$1085,"<="&Paramètres!$C$10),"") | H8: =IFERROR(SUMIF(Clients!$J$2:$J$1020,">="&LARGE(Clients!$J$2:$J$1020,MAX(1,ROUND(COUNTIF(Clients!$J$2:$J$1020,">0")*0.1,0))))/SUM(Clients!$J$2:$J$1020),"") | K8: =IFERROR(365.0*(SUMIFS(Factures!$X$2:$X$1085,Factures!$F$2:$F$1085,">="&Paramètres!$C$9,Factures!$F$2:$F$1085,"<="&Paramètres!$C$10)/SUMIFS(Factures!$M$2:$M$1085,Factures!$F$2:$F$1085,">="&Paramètres!$C$9,Factures!$F$2:$F$1085,"<="&Paramètres!$C$10)),"")
B9: =IFERROR((IFERROR(SUMIFS(Interventions!$R$2:$R$1106,Interventions!$C$2:$C$1106,">="&Paramètres!$C$9,Interventions!$C$2:$C$1106,"<="&Paramètres!$C$10)/SUMIFS(Interventions!$V$2:$V$1106,Interventions!$C$2:$C$1106,">="&Paramètres!$C$9,Interventions!$C$2:$C$1106,"<="&Paramètres!$C$10),""))/(IFERROR(SUMIFS(Interventions!$R$2:$R$1106,Interventions!$C$2:$C$1106,">="&Paramètres!$C$11,Interventions!$C$2:$C$1106,"<="&Paramètres!$C$12)/SUMIFS(Interventions!$W$2:$W$1106,Interventions!$C$2:$C$1106,">="&Paramètres!$C$11,Interventions!$C$2:$C$1106,"<="&Paramètres!$C$12),""))-1,"") | E9: =IFERROR((IFERROR(SUMIFS(Factures!$V$2:$V$1085,Factures!$F$2:$F$1085,">="&Paramètres!$C$9,Factures!$F$2:$F$1085,"<="&Paramètres!$C$10)/SUMIFS(Factures!$K$2:$K$1085,Factures!$F$2:$F$1085,">="&Paramètres!$C$9,Factures!$F$2:$F$1085,"<="&Paramètres!$C$10),""))/(IFERROR(SUMIFS(Factures!$V$2:$V$1085,Factures!$F$2:$F$1085,">="&Paramètres!$C$11,Factures!$F$2:$F$1085,"<="&Paramètres!$C$12)/SUMIFS(Factures!$K$2:$K$1085,Factures!$F$2:$F$1085,">="&Paramètres!$C$11,Factures!$F$2:$F$1085,"<="&Paramètres!$C$12),""))-1,"") | H9: =IFERROR((IFERROR(SUMIF(Clients!$J$2:$J$1020,">="&LARGE(Clients!$J$2:$J$1020,MAX(1,ROUND(COUNTIF(Clients!$J$2:$J$1020,">0")*0.1,0))))/SUM(Clients!$J$2:$J$1020),""))/(IFERROR(SUMIF(Clients!$K$2:$K$1020,">="&LARGE(Clients!$K$2:$K$1020,MAX(1,ROUND(COUNTIF(Clients!$K$2:$K$1020,">0")*0.1,0))))/SUM(Clients!$K$2:$K$1020),""))-1,"") | K9: état à la date de situation
B11: TAUX DE TRANSFORMATION DES DEVIS · PAR AGENCE | E11: PANIER MOYEN D'UN DEVIS GAGNÉ · PAR TYPE DE CLIENT
B12: =IFERROR(SUMIFS(Devis!$X$2:$X$3053,Devis!$B$2:$B$3053,">="&Paramètres!$C$9,Devis!$B$2:$B$3053,"<="&Paramètres!$C$10)/SUMIFS(Devis!$Y$2:$Y$3053,Devis!$B$2:$B$3053,">="&Paramètres!$C$9,Devis!$B$2:$B$3053,"<="&Paramètres!$C$10),"") | E12: =IFERROR(SUMIFS(Devis!$X$2:$X$3053,Devis!$B$2:$B$3053,">="&Paramètres!$C$9,Devis!$B$2:$B$3053,"<="&Paramètres!$C$10)/SUMIFS(Devis!$W$2:$W$3053,Devis!$B$2:$B$3053,">="&Paramètres!$C$9,Devis!$B$2:$B$3053,"<="&Paramètres!$C$10),"")
B13: =IFERROR((IFERROR(SUMIFS(Devis!$X$2:$X$3053,Devis!$B$2:$B$3053,">="&Paramètres!$C$9,Devis!$B$2:$B$3053,"<="&Paramètres!$C$10)/SUMIFS(Devis!$Y$2:$Y$3053,Devis!$B$2:$B$3053,">="&Paramètres!$C$9,Devis!$B$2:$B$3053,"<="&Paramètres!$C$10),""))/(IFERROR(SUMIFS(Devis!$X$2:$X$3053,Devis!$B$2:$B$3053,">="&Paramètres!$C$11,Devis!$B$2:$B$3053,"<="&Paramètres!$C$12)/SUMIFS(Devis!$Y$2:$Y$3053,Devis!$B$2:$B$3053,">="&Paramètres!$C$11,Devis!$B$2:$B$3053,"<="&Paramètres!$C$12),""))-1,"") | E13: =IFERROR((IFERROR(SUMIFS(Devis!$X$2:$X$3053,Devis!$B$2:$B$3053,">="&Paramètres!$C$9,Devis!$B$2:$B$3053,"<="&Paramètres!$C$10)/SUMIFS(Devis!$W$2:$W$3053,Devis!$B$2:$B$3053,">="&Paramètres!$C$9,Devis!$B$2:$B$3053,"<="&Paramètres!$C$10),""))/(IFERROR(SUMIFS(Devis!$X$2:$X$3053,Devis!$B$2:$B$3053,">="&Paramètres!$C$11,Devis!$B$2:$B$3053,"<="&Paramètres!$C$12)/SUMIFS(Devis!$W$2:$W$3053,Devis!$B$2:$B$3053,">="&Paramètres!$C$11,Devis!$B$2:$B$3053,"<="&Paramètres!$C$12),""))-1,"")
B14: Ligne du haut : socle imposé, comparable d'une édition à l'autre. Ligne du bas : indicateurs retenus pour cette période.
B16: Chiffre d'affaires facturé et taux de marge
B35: Décomposition de l'écart de chiffre d'affaires
B36: Métier | C36: Affaires N-1 | D36: Panier N-1 | E36: Affaires N | F36: Panier N
B37: Chauffage | C37: =COUNTIFS(Factures!$F$2:$F$1085,">="&Paramètres!$C$11,Factures!$F$2:$F$1085,"<="&Paramètres!$C$12,Factures!$Q$2:$Q$1085,$B37) | D37: =IFERROR(SUMIFS(Factures!$K$2:$K$1085,Factures!$F$2:$F$1085,">="&Paramètres!$C$11,Factures!$F$2:$F$1085,"<="&Paramètres!$C$12,Factures!$Q$2:$Q$1085,$B37)/$C37,0) | E37: =COUNTIFS(Factures!$F$2:$F$1085,">="&Paramètres!$C$9,Factures!$F$2:$F$1085,"<="&Paramètres!$C$10,Factures!$Q$2:$Q$1085,$B37) | F37: =IFERROR(SUMIFS(Factures!$K$2:$K$1085,Factures!$F$2:$F$1085,">="&Paramètres!$C$9,Factures!$F$2:$F$1085,"<="&Paramètres!$C$10,Factures!$Q$2:$Q$1085,$B37)/$E37,0)
B38: Dépannage | C38: =COUNTIFS(Factures!$F$2:$F$1085,">="&Paramètres!$C$11,Factures!$F$2:$F$1085,"<="&Paramètres!$C$12,Factures!$Q$2:$Q$1085,$B38) | D38: =IFERROR(SUMIFS(Factures!$K$2:$K$1085,Factures!$F$2:$F$1085,">="&Paramètres!$C$11,Factures!$F$2:$F$1085,"<="&Paramètres!$C$12,Factures!$Q$2:$Q$1085,$B38)/$C38,0) | E38: =COUNTIFS(Factures!$F$2:$F$1085,">="&Paramètres!$C$9,Factures!$F$2:$F$1085,"<="&Paramètres!$C$10,Factures!$Q$2:$Q$1085,$B38) | F38: =IFERROR(SUMIFS(Factures!$K$2:$K$1085,Factures!$F$2:$F$1085,">="&Paramètres!$C$9,Factures!$F$2:$F$1085,"<="&Paramètres!$C$10,Factures!$Q$2:$Q$1085,$B38)/$E38,0)
B39: Plomberie | C39: =COUNTIFS(Factures!$F$2:$F$1085,">="&Paramètres!$C$11,Factures!$F$2:$F$1085,"<="&Paramètres!$C$12,Factures!$Q$2:$Q$1085,$B39) | D39: =IFERROR(SUMIFS(Factures!$K$2:$K$1085,Factures!$F$2:$F$1085,">="&Paramètres!$C$11,Factures!$F$2:$F$1085,"<="&Paramètres!$C$12,Factures!$Q$2:$Q$1085,$B39)/$C39,0) | E39: =COUNTIFS(Factures!$F$2:$F$1085,">="&Paramètres!$C$9,Factures!$F$2:$F$1085,"<="&Paramètres!$C$10,Factures!$Q$2:$Q$1085,$B39) | F39: =IFERROR(SUMIFS(Factures!$K$2:$K$1085,Factures!$F$2:$F$1085,">="&Paramètres!$C$9,Factures!$F$2:$F$1085,"<="&Paramètres!$C$10,Factures!$Q$2:$Q$1085,$B39)/$E39,0)
B40: Salle de bain | C40: =COUNTIFS(Factures!$F$2:$F$1085,">="&Paramètres!$C$11,Factures!$F$2:$F$1085,"<="&Paramètres!$C$12,Factures!$Q$2:$Q$1085,$B40) | D40: =IFERROR(SUMIFS(Factures!$K$2:$K$1085,Factures!$F$2:$F$1085,">="&Paramètres!$C$11,Factures!$F$2:$F$1085,"<="&Paramètres!$C$12,Factures!$Q$2:$Q$1085,$B40)/$C40,0) | E40: =COUNTIFS(Factures!$F$2:$F$1085,">="&Paramètres!$C$9,Factures!$F$2:$F$1085,"<="&Paramètres!$C$10,Factures!$Q$2:$Q$1085,$B40) | F40: =IFERROR(SUMIFS(Factures!$K$2:$K$1085,Factures!$F$2:$F$1085,">="&Paramètres!$C$9,Factures!$F$2:$F$1085,"<="&Paramètres!$C$10,Factures!$Q$2:$Q$1085,$B40)/$E40,0)
B41: Électricité | C41: =COUNTIFS(Factures!$F$2:$F$1085,">="&Paramètres!$C$11,Factures!$F$2:$F$1085,"<="&Paramètres!$C$12,Factures!$Q$2:$Q$1085,$B41) | D41: =IFERROR(SUMIFS(Factures!$K$2:$K$1085,Factures!$F$2:$F$1085,">="&Paramètres!$C$11,Factures!$F$2:$F$1085,"<="&Paramètres!$C$12,Factures!$Q$2:$Q$1085,$B41)/$C41,0) | E41: =COUNTIFS(Factures!$F$2:$F$1085,">="&Paramètres!$C$9,Factures!$F$2:$F$1085,"<="&Paramètres!$C$10,Factures!$Q$2:$Q$1085,$B41) | F41: =IFERROR(SUMIFS(Factures!$K$2:$K$1085,Factures!$F$2:$F$1085,">="&Paramètres!$C$9,Factures!$F$2:$F$1085,"<="&Paramètres!$C$10,Factures!$Q$2:$Q$1085,$B41)/$E41,0)
B42: Ensemble | C42: =SUM($C37:$C41) | D42: =IFERROR(SUMPRODUCT($C37:$C41,$D37:$D41)/$C42,0) | E42: =SUM($E37:$E41) | F42: =IFERROR(SUMPRODUCT($E37:$E41,$F37:$F41)/$E42,0)
B44: Ponts d'écart
B45: Effet | C45: Montant | D45: Lecture
B46: Volume | C46: =($E42-$C42)*$D42 | D46: Davantage d'affaires, au panier moyen de l'an dernier.
B47: Mix | C47: =IFERROR($E42*(SUMPRODUCT($E37:$E41,$D37:$D41)/$E42-$D42),0) | D47: Déformation de la répartition entre métiers, à prix constants.
B48: Prix | C48: =IFERROR($E42*($F42-SUMPRODUCT($E37:$E41,$D37:$D41)/$E42),0) | D48: Variation du panier à structure constante.
B49: Écart total | C49: =SUM($C46:$C48) | D49: Égal, par construction, à la variation du chiffre d'affaires facturé.
B51: Pont commercial — devis gagnés
B52: Effet | C52: Montant | D52: Lecture
B53: Volume devisé | C53: =IFERROR((SUMIFS(Devis!$Y$2:$Y$3053,Devis!$B$2:$B$3053,">="&Paramètres!$C$9,Devis!$B$2:$B$3053,"<="&Paramètres!$C$10)-SUMIFS(Devis!$Y$2:$Y$3053,Devis!$B$2:$B$3053,">="&Paramètres!$C$11,Devis!$B$2:$B$3053,"<="&Paramètres!$C$12))*(SUMIFS(Devis!$X$2:$X$3053,Devis!$B$2:$B$3053,">="&Paramètres!$C$11,Devis!$B$2:$B$3053,"<="&Paramètres!$C$12))/(SUMIFS(Devis!$Y$2:$Y$3053,Devis!$B$2:$B$3053,">="&Paramètres!$C$11,Devis!$B$2:$B$3053,"<="&Paramètres!$C$12)),0) | D53: Effet du volume de devis émis, à taux de transformation constant.
B54: Transformation | C54: =IFERROR((SUMIFS(Devis!$Y$2:$Y$3053,Devis!$B$2:$B$3053,">="&Paramètres!$C$9,Devis!$B$2:$B$3053,"<="&Paramètres!$C$10))*((SUMIFS(Devis!$X$2:$X$3053,Devis!$B$2:$B$3053,">="&Paramètres!$C$9,Devis!$B$2:$B$3053,"<="&Paramètres!$C$10))/(SUMIFS(Devis!$Y$2:$Y$3053,Devis!$B$2:$B$3053,">="&Paramètres!$C$9,Devis!$B$2:$B$3053,"<="&Paramètres!$C$10))-(SUMIFS(Devis!$X$2:$X$3053,Devis!$B$2:$B$3053,">="&Paramètres!$C$11,Devis!$B$2:$B$3053,"<="&Paramètres!$C$12))/(SUMIFS(Devis!$Y$2:$Y$3053,Devis!$B$2:$B$3053,">="&Paramètres!$C$11,Devis!$B$2:$B$3053,"<="&Paramètres!$C$12))),0) | D54: Effet du taux de transformation, à volume constant.
B55: Écart total | C55: =SUM($C53:$C54) | D55: Égal à la variation du chiffre d'affaires gagné sur devis.
B57: Points d'attention
B58: La trajectoire est celle d'une entreprise qui produit davantage mais dont la profitabilité et l'encaissement se dégradient — l'effort commercial doit se concentrer sur les zones de conversion faible et la politique tarifaire doit être revue sur le segment dominant.
B59: Taux de transformation des devis — Revoir le dispositif commercial de l'agence la plus faible, en s'inspirant de l'agence de tête, et fixer un plan de retour à la moyenne.
B60: Panier moyen d'un devis gagné — Repréciser la grille tarifaire et les propositions d'options sur le segment Particulier pour remonter le panier moyen.
B61: Écartée — Le taux de marge brute sur les Particuliers est structurellement plus faible que sur les autres clientèles. : L'écart existe mais la mesure de marge brute est déjà couverte par le socle imposé, doublonner ferait perdre en lisibilité.
B62: Écartée — Le taux de transformation sur Chauffage est dégradé et pèse sur l'ensemble de l'activité. : L'écart est réel mais la Plomberie présente un niveau équivalent : aucun coupable métier isolé, donc aucune décision ciblée possible.
B63: Écartée — Un effet combiné métier × agence existe sur la marge de la Salle de bain. : Le croisement ne révèle aucune cellule Sala de bain × agence suffisamment peuplée et distinctive : l'hypothèse n'est pas démontrable.
B64: Écartée — Le DSO dégradé provient du canal Site web, sur lequel le dirigeant peut agir. : Confirmée mais la mesure DSO est déjà dans le socle imposé : pas un indicateur à choisir.

Sheet Indicateurs
B2: B Â T I - S U D · G R O U P E A R T I S A N A L
B3: Indicateurs retenus | I3: Détail
B4: Un bloc par indicateur : ventilation, comparaison et décision attendue.
B7: Taux de transformation des devis par agence
B8: L'écart entre agences est massif et stable, avec une agence très en retrait qui n'est pas réductible à un effet de volume.
B9: Modalité | C9: Valeur | D9: Effectif | E9: Période précédente | F9: Écart | G9: Part du total
B10: Bordeaux | C10: =IFERROR(SUMIFS(Devis!$X$2:$X$3053,Devis!$B$2:$B$3053,">="&Paramètres!$C$9,Devis!$B$2:$B$3053,"<="&Paramètres!$C$10,Devis!$G$2:$G$3053,"Bordeaux")/SUMIFS(Devis!$Y$2:$Y$3053,Devis!$B$2:$B$3053,">="&Paramètres!$C$9,Devis!$B$2:$B$3053,"<="&Paramètres!$C$10,Devis!$G$2:$G$3053,"Bordeaux"),"") | D10: =COUNTIFS(Devis!$B$2:$B$3053,">="&Paramètres!$C$9,Devis!$B$2:$B$3053,"<="&Paramètres!$C$10,Devis!$G$2:$G$3053,"Bordeaux") | E10: =IFERROR(SUMIFS(Devis!$X$2:$X$3053,Devis!$B$2:$B$3053,">="&Paramètres!$C$11,Devis!$B$2:$B$3053,"<="&Paramètres!$C$12,Devis!$G$2:$G$3053,"Bordeaux")/SUMIFS(Devis!$Y$2:$Y$3053,Devis!$B$2:$B$3053,">="&Paramètres!$C$11,Devis!$B$2:$B$3053,"<="&Paramètres!$C$12,Devis!$G$2:$G$3053,"Bordeaux"),"") | F10: =IFERROR($C10/$E10-1,"") | G10: =IFERROR(SUMIFS(Devis!$X$2:$X$3053,Devis!$B$2:$B$3053,">="&Paramètres!$C$9,Devis!$B$2:$B$3053,"<="&Paramètres!$C$10,Devis!$G$2:$G$3053,"Bordeaux")/SUMIFS(Devis!$X$2:$X$3053,Devis!$B$2:$B$3053,">="&Paramètres!$C$9,Devis!$B$2:$B$3053,"<="&Paramètres!$C$10),"")
B11: Montpellier | C11: =IFERROR(SUMIFS(Devis!$X$2:$X$3053,Devis!$B$2:$B$3053,">="&Paramètres!$C$9,Devis!$B$2:$B$3053,"<="&Paramètres!$C$10,Devis!$G$2:$G$3053,"Montpellier")/SUMIFS(Devis!$Y$2:$Y$3053,Devis!$B$2:$B$3053,">="&Paramètres!$C$9,Devis!$B$2:$B$3053,"<="&Paramètres!$C$10,Devis!$G$2:$G$3053,"Montpellier"),"") | D11: =COUNTIFS(Devis!$B$2:$B$3053,">="&Paramètres!$C$9,Devis!$B$2:$B$3053,"<="&Paramètres!$C$10,Devis!$G$2:$G$3053,"Montpellier") | E11: =IFERROR(SUMIFS(Devis!$X$2:$X$3053,Devis!$B$2:$B$3053,">="&Paramètres!$C$11,Devis!$B$2:$B$3053,"<="&Paramètres!$C$12,Devis!$G$2:$G$3053,"Montpellier")/SUMIFS(Devis!$Y$2:$Y$3053,Devis!$B$2:$B$3053,">="&Paramètres!$C$11,Devis!$B$2:$B$3053,"<="&Paramètres!$C$12,Devis!$G$2:$G$3053,"Montpellier"),"") | F11: =IFERROR($C11/$E11-1,"") | G11: =IFERROR(SUMIFS(Devis!$X$2:$X$3053,Devis!$B$2:$B$3053,">="&Paramètres!$C$9,Devis!$B$2:$B$3053,"<="&Paramètres!$C$10,Devis!$G$2:$G$3053,"Montpellier")/SUMIFS(Devis!$X$2:$X$3053,Devis!$B$2:$B$3053,">="&Paramètres!$C$9,Devis!$B$2:$B$3053,"<="&Paramètres!$C$10),"")
B12: Toulouse | C12: =IFERROR(SUMIFS(Devis!$X$2:$X$3053,Devis!$B$2:$B$3053,">="&Paramètres!$C$9,Devis!$B$2:$B$3053,"<="&Paramètres!$C$10,Devis!$G$2:$G$3053,"Toulouse")/SUMIFS(Devis!$Y$2:$Y$3053,Devis!$B$2:$B$3053,">="&Paramètres!$C$9,Devis!$B$2:$B$3053,"<="&Paramètres!$C$10,Devis!$G$2:$G$3053,"Toulouse"),"") | D12: =COUNTIFS(Devis!$B$2:$B$3053,">="&Paramètres!$C$9,Devis!$B$2:$B$3053,"<="&Paramètres!$C$10,Devis!$G$2:$G$3053,"Toulouse") | E12: =IFERROR(SUMIFS(Devis!$X$2:$X$3053,Devis!$B$2:$B$3053,">="&Paramètres!$C$11,Devis!$B$2:$B$3053,"<="&Paramètres!$C$12,Devis!$G$2:$G$3053,"Toulouse")/SUMIFS(Devis!$Y$2:$Y$3053,Devis!$B$2:$B$3053,">="&Paramètres!$C$11,Devis!$B$2:$B$3053,"<="&Paramètres!$C$12,Devis!$G$2:$G$3053,"Toulouse"),"") | F12: =IFERROR($C12/$E12-1,"") | G12: =IFERROR(SUMIFS(Devis!$X$2:$X$3053,Devis!$B$2:$B$3053,">="&Paramètres!$C$9,Devis!$B$2:$B$3053,"<="&Paramètres!$C$10,Devis!$G$2:$G$3053,"Toulouse")/SUMIFS(Devis!$X$2:$X$3053,Devis!$B$2:$B$3053,">="&Paramètres!$C$9,Devis!$B$2:$B$3053,"<="&Paramètres!$C$10),"")
B13: Ensemble | C13: =IFERROR(SUMIFS(Devis!$X$2:$X$3053,Devis!$B$2:$B$3053,">="&Paramètres!$C$9,Devis!$B$2:$B$3053,"<="&Paramètres!$C$10)/SUMIFS(Devis!$Y$2:$Y$3053,Devis!$B$2:$B$3053,">="&Paramètres!$C$9,Devis!$B$2:$B$3053,"<="&Paramètres!$C$10),"") | D13: =COUNTIFS(Devis!$B$2:$B$3053,">="&Paramètres!$C$9,Devis!$B$2:$B$3053,"<="&Paramètres!$C$10) | E13: =IFERROR(SUMIFS(Devis!$X$2:$X$3053,Devis!$B$2:$B$3053,">="&Paramètres!$C$11,Devis!$B$2:$B$3053,"<="&Paramètres!$C$12)/SUMIFS(Devis!$Y$2:$Y$3053,Devis!$B$2:$B$3053,">="&Paramètres!$C$11,Devis!$B$2:$B$3053,"<="&Paramètres!$C$12),"") | F13: =IFERROR($C13/$E13-1,"") | G13: =1
B14: Décision attendue : Revoir le dispositif commercial de l'agence la plus faible, en s'inspirant de l'agence de tête, et fixer un plan de retour à la moyenne.
B23: Panier moyen d'un devis gagné par type de client
B24: Le segment dominant du portefeuille est nettement en deçà des autres clientèles, confirmant un manque à gagner matériel sur l'année.
B25: Modalité | C25: Valeur | D25: Effectif | E25: Période précédente | F25: Écart | G25: Part du total
B26: Collectivité | C26: =IFERROR(SUMIFS(Devis!$X$2:$X$3053,Devis!$B$2:$B$3053,">="&Paramètres!$C$9,Devis!$B$2:$B$3053,"<="&Paramètres!$C$10,Devis!$F$2:$F$3053,"Collectivité")/SUMIFS(Devis!$W$2:$W$3053,Devis!$B$2:$B$3053,">="&Paramètres!$C$9,Devis!$B$2:$B$3053,"<="&Paramètres!$C$10,Devis!$F$2:$F$3053,"Collectivité"),"") | D26: =COUNTIFS(Devis!$B$2:$B$3053,">="&Paramètres!$C$9,Devis!$B$2:$B$3053,"<="&Paramètres!$C$10,Devis!$F$2:$F$3053,"Collectivité") | E26: =IFERROR(SUMIFS(Devis!$X$2:$X$3053,Devis!$B$2:$B$3053,">="&Paramètres!$C$11,Devis!$B$2:$B$3053,"<="&Paramètres!$C$12,Devis!$F$2:$F$3053,"Collectivité")/SUMIFS(Devis!$W$2:$W$3053,Devis!$B$2:$B$3053,">="&Paramètres!$C$11,Devis!$B$2:$B$3053,"<="&Paramètres!$C$12,Devis!$F$2:$F$3053,"Collectivité"),"") | F26: =IFERROR($C26/$E26-1,"") | G26: =IFERROR(SUMIFS(Devis!$X$2:$X$3053,Devis!$B$2:$B$3053,">="&Paramètres!$C$9,Devis!$B$2:$B$3053,"<="&Paramètres!$C$10,Devis!$F$2:$F$3053,"Collectivité")/SUMIFS(Devis!$X$2:$X$3053,Devis!$B$2:$B$3053,">="&Paramètres!$C$9,Devis!$B$2:$B$3053,"<="&Paramètres!$C$10),"")
B27: Particulier | C27: =IFERROR(SUMIFS(Devis!$X$2:$X$3053,Devis!$B$2:$B$3053,">="&Paramètres!$C$9,Devis!$B$2:$B$3053,"<="&Paramètres!$C$10,Devis!$F$2:$F$3053,"Particulier")/SUMIFS(Devis!$W$2:$W$3053,Devis!$B$2:$B$3053,">="&Paramètres!$C$9,Devis!$B$2:$B$3053,"<="&Paramètres!$C$10,Devis!$F$2:$F$3053,"Particulier"),"") | D27: =COUNTIFS(Devis!$B$2:$B$3053,">="&Paramètres!$C$9,Devis!$B$2:$B$3053,"<="&Paramètres!$C$10,Devis!$F$2:$F$3053,"Particulier") | E27: =IFERROR(SUMIFS(Devis!$X$2:$X$3053,Devis!$B$2:$B$3053,">="&Paramètres!$C$11,Devis!$B$2:$B$3053,"<="&Paramètres!$C$12,Devis!$F$2:$F$3053,"Particulier")/SUMIFS(Devis!$W$2:$W$3053,Devis!$B$2:$B$3053,">="&Paramètres!$C$11,Devis!$B$2:$B$3053,"<="&Paramètres!$C$12,Devis!$F$2:$F$3053,"Particulier"),"") | F27: =IFERROR($C27/$E27-1,"") | G27: =IFERROR(SUMIFS(Devis!$X$2:$X$3053,Devis!$B$2:$B$3053,">="&Paramètres!$C$9,Devis!$B$2:$B$3053,"<="&Paramètres!$C$10,Devis!$F$2:$F$3053,"Particulier")/SUMIFS(Devis!$X$2:$X$3053,Devis!$B$2:$B$3053,">="&Paramètres!$C$9,Devis!$B$2:$B$3053,"<="&Paramètres!$C$10),"")
B28: Professionnel | C28: =IFERROR(SUMIFS(Devis!$X$2:$X$3053,Devis!$B$2:$B$3053,">="&Paramètres!$C$9,Devis!$B$2:$B$3053,"<="&Paramètres!$C$10,Devis!$F$2:$F$3053,"Professionnel")/SUMIFS(Devis!$W$2:$W$3053,Devis!$B$2:$B$3053,">="&Paramètres!$C$9,Devis!$B$2:$B$3053,"<="&Paramètres!$C$10,Devis!$F$2:$F$3053,"Professionnel"),"") | D28: =COUNTIFS(Devis!$B$2:$B$3053,">="&Paramètres!$C$9,Devis!$B$2:$B$3053,"<="&Paramètres!$C$10,Devis!$F$2:$F$3053,"Professionnel") | E28: =IFERROR(SUMIFS(Devis!$X$2:$X$3053,Devis!$B$2:$B$3053,">="&Paramètres!$C$11,Devis!$B$2:$B$3053,"<="&Paramètres!$C$12,Devis!$F$2:$F$3053,"Professionnel")/SUMIFS(Devis!$W$2:$W$3053,Devis!$B$2:$B$3053,">="&Paramètres!$C$11,Devis!$B$2:$B$3053,"<="&Paramètres!$C$12,Devis!$F$2:$F$3053,"Professionnel"),"") | F28: =IFERROR($C28/$E28-1,"") | G28: =IFERROR(SUMIFS(Devis!$X$2:$X$3053,Devis!$B$2:$B$3053,">="&Paramètres!$C$9,Devis!$B$2:$B$3053,"<="&Paramètres!$C$10,Devis!$F$2:$F$3053,"Professionnel")/SUMIFS(Devis!$X$2:$X$3053,Devis!$B$2:$B$3053,">="&Paramètres!$C$9,Devis!$B$2:$B$3053,"<="&Paramètres!$C$10),"")
B29: Syndic | C29: =IFERROR(SUMIFS(Devis!$X$2:$X$3053,Devis!$B$2:$B$3053,">="&Paramètres!$C$9,Devis!$B$2:$B$3053,"<="&Paramètres!$C$10,Devis!$F$2:$F$3053,"Syndic")/SUMIFS(Devis!$W$2:$W$3053,Devis!$B$2:$B$3053,">="&Paramètres!$C$9,Devis!$B$2:$B$3053,"<="&Paramètres!$C$10,Devis!$F$2:$F$3053,"Syndic"),"") | D29: =COUNTIFS(Devis!$B$2:$B$3053,">="&Paramètres!$C$9,Devis!$B$2:$B$3053,"<="&Paramètres!$C$10,Devis!$F$2:$F$3053,"Syndic") | E29: =IFERROR(SUMIFS(Devis!$X$2:$X$3053,Devis!$B$2:$B$3053,">="&Paramètres!$C$11,Devis!$B$2:$B$3053,"<="&Paramètres!$C$12,Devis!$F$2:$F$3053,"Syndic")/SUMIFS(Devis!$W$2:$W$3053,Devis!$B$2:$B$3053,">="&Paramètres!$C$11,Devis!$B$2:$B$3053,"<="&Paramètres!$C$12,Devis!$F$2:$F$3053,"Syndic"),"") | F29: =IFERROR($C29/$E29-1,"") | G29: =IFERROR(SUMIFS(Devis!$X$2:$X$3053,Devis!$B$2:$B$3053,">="&Paramètres!$C$9,Devis!$B$2:$B$3053,"<="&Paramètres!$C$10,Devis!$F$2:$F$3053,"Syndic")/SUMIFS(Devis!$X$2:$X$3053,Devis!$B$2:$B$3053,">="&Paramètres!$C$9,Devis!$B$2:$B$3053,"<="&Paramètres!$C$10),"")
B30: Ensemble | C30: =IFERROR(SUMIFS(Devis!$X$2:$X$3053,Devis!$B$2:$B$3053,">="&Paramètres!$C$9,Devis!$B$2:$B$3053,"<="&Paramètres!$C$10)/SUMIFS(Devis!$W$2:$W$3053,Devis!$B$2:$B$3053,">="&Paramètres!$C$9,Devis!$B$2:$B$3053,"<="&Paramètres!$C$10),"") | D30: =COUNTIFS(Devis!$B$2:$B$3053,">="&Paramètres!$C$9,Devis!$B$2:$B$3053,"<="&Paramètres!$C$10) | E30: =IFERROR(SUMIFS(Devis!$X$2:$X$3053,Devis!$B$2:$B$3053,">="&Paramètres!$C$11,Devis!$B$2:$B$3053,"<="&Paramètres!$C$12)/SUMIFS(Devis!$W$2:$W$3053,Devis!$B$2:$B$3053,">="&Paramètres!$C$11,Devis!$B$2:$B$3053,"<="&Paramètres!$C$12),"") | F30: =IFERROR($C30/$E30-1,"") | G30: =1
B31: Décision attendue : Repréciser la grille tarifaire et les propositions d'options sur le segment Particulier pour remonter le panier moyen.

Sheet Détail mensuel
B2: B Â T I - S U D · G R O U P E A R T I S A N A L
B3: Détail mensuel | J3: Données de série
B4: Source des graphiques de la synthèse. Une ligne par mois, sur toute la période.
B7: Série mensuelle
B8: Mois | C8: CA facturé HT | D8: Coût de revient | E8: Marge brute | F8: Taux de marge | G8: Devis émis HT | H8: Devis arbitrés HT | I8: Devis gagnés HT | J8: Taux de transformation | K8: Encaissements TTC
B9: 2022-07 | C9: =SUMIFS(Factures!$K$2:$K$1085,Factures!$G$2:$G$1085,$B9) | D9: =SUMIFS(Factures!$U$2:$U$1085,Factures!$G$2:$G$1085,$B9) | E9: =$C9-$D9 | F9: =IFERROR($E9/$C9,"") | G9: =SUMIFS(Devis!$M$2:$M$3053,Devis!$C$2:$C$3053,$B9) | H9: =SUMIFS(Devis!$Y$2:$Y$3053,Devis!$C$2:$C$3053,$B9) | I9: =SUMIFS(Devis!$X$2:$X$3053,Devis!$C$2:$C$3053,$B9) | J9: =IFERROR($I9/$H9,"") | K9: =SUMIFS(Factures!$M$2:$M$1085,Factures!$AD$2:$AD$1085,$B9)
B10: 2022-08 | C10: =SUMIFS(Factures!$K$2:$K$1085,Factures!$G$2:$G$1085,$B10) | D10: =SUMIFS(Factures!$U$2:$U$1085,Factures!$G$2:$G$1085,$B10) | E10: =$C10-$D10 | F10: =IFERROR($E10/$C10,"") | G10: =SUMIFS(Devis!$M$2:$M$3053,Devis!$C$2:$C$3053,$B10) | H10: =SUMIFS(Devis!$Y$2:$Y$3053,Devis!$C$2:$C$3053,$B10) | I10: =SUMIFS(Devis!$X$2:$X$3053,Devis!$C$2:$C$3053,$B10) | J10: =IFERROR($I10/$H10,"") | K10: =SUMIFS(Factures!$M$2:$M$1085,Factures!$AD$2:$AD$1085,$B10)
B11: 2022-09 | C11: =SUMIFS(Factures!$K$2:$K$1085,Factures!$G$2:$G$1085,$B11) | D11: =SUMIFS(Factures!$U$2:$U$1085,Factures!$G$2:$G$1085,$B11) | E11: =$C11-$D11 | F11: =IFERROR($E11/$C11,"") | G11: =SUMIFS(Devis!$M$2:$M$3053,Devis!$C$2:$C$3053,$B11) | H11: =SUMIFS(Devis!$Y$2:$Y$3053,Devis!$C$2:$C$3053,$B11) | I11: =SUMIFS(Devis!$X$2:$X$3053,Devis!$C$2:$C$3053,$B11) | J11: =IFERROR($I11/$H11,"") | K11: =SUMIFS(Factures!$M$2:$M$1085,Factures!$AD$2:$AD$1085,$B11)
B12: 2022-10 | C12: =SUMIFS(Factures!$K$2:$K$1085,Factures!$G$2:$G$1085,$B12) | D12: =SUMIFS(Factures!$U$2:$U$1085,Factures!$G$2:$G$1085,$B12) | E12: =$C12-$D12 | F12: =IFERROR($E12/$C12,"") | G12: =SUMIFS(Devis!$M$2:$M$3053,Devis!$C$2:$C$3053,$B12) | H12: =SUMIFS(Devis!$Y$2:$Y$3053,Devis!$C$2:$C$3053,$B12) | I12: =SUMIFS(Devis!$X$2:$X$3053,Devis!$C$2:$C$3053,$B12) | J12: =IFERROR($I12/$H12,"") | K12: =SUMIFS(Factures!$M$2:$M$1085,Factures!$AD$2:$AD$1085,$B12)
B13: 2022-11 | C13: =SUMIFS(Factures!$K$2:$K$1085,Factures!$G$2:$G$1085,$B13) | D13: =SUMIFS(Factures!$U$2:$U$1085,Factures!$G$2:$G$1085,$B13) | E13: =$C13-$D13 | F13: =IFERROR($E13/$C13,"") | G13: =SUMIFS(Devis!$M$2:$M$3053,Devis!$C$2:$C$3053,$B13) | H13: =SUMIFS(Devis!$Y$2:$Y$3053,Devis!$C$2:$C$3053,$B13) | I13: =SUMIFS(Devis!$X$2:$X$3053,Devis!$C$2:$C$3053,$B13) | J13: =IFERROR($I13/$H13,"") | K13: =SUMIFS(Factures!$M$2:$M$1085,Factures!$AD$2:$AD$1085,$B13)
B14: 2022-12 | C14: =SUMIFS(Factures!$K$2:$K$1085,Factures!$G$2:$G$1085,$B14) | D14: =SUMIFS(Factures!$U$2:$U$1085,Factures!$G$2:$G$1085,$B14) | E14: =$C14-$D14 | F14: =IFERROR($E14/$C14,"") | G14: =SUMIFS(Devis!$M$2:$M$3053,Devis!$C$2:$C$3053,$B14) | H14: =SUMIFS(Devis!$Y$2:$Y$3053,Devis!$C$2:$C$3053,$B14) | I14: =SUMIFS(Devis!$X$2:$X$3053,Devis!$C$2:$C$3053,$B14) | J14: =IFERROR($I14/$H14,"") | K14: =SUMIFS(Factures!$M$2:$M$1085,Factures!$AD$2:$AD$1085,$B14)
B15: 2023-01 | C15: =SUMIFS(Factures!$K$2:$K$1085,Factures!$G$2:$G$1085,$B15) | D15: =SUMIFS(Factures!$U$2:$U$1085,Factures!$G$2:$G$1085,$B15) | E15: =$C15-$D15 | F15: =IFERROR($E15/$C15,"") | G15: =SUMIFS(Devis!$M$2:$M$3053,Devis!$C$2:$C$3053,$B15) | H15: =SUMIFS(Devis!$Y$2:$Y$3053,Devis!$C$2:$C$3053,$B15) | I15: =SUMIFS(Devis!$X$2:$X$3053,Devis!$C$2:$C$3053,$B15) | J15: =IFERROR($I15/$H15,"") | K15: =SUMIFS(Factures!$M$2:$M$1085,Factures!$AD$2:$AD$1085,$B15)
B16: 2023-02 | C16: =SUMIFS(Factures!$K$2:$K$1085,Factures!$G$2:$G$1085,$B16) | D16: =SUMIFS(Factures!$U$2:$U$1085,Factures!$G$2:$G$1085,$B16) | E16: =$C16-$D16 | F16: =IFERROR($E16/$C16,"") | G16: =SUMIFS(Devis!$M$2:$M$3053,Devis!$C$2:$C$3053,$B16) | H16: =SUMIFS(Devis!$Y$2:$Y$3053,Devis!$C$2:$C$3053,$B16) | I16: =SUMIFS(Devis!$X$2:$X$3053,Devis!$C$2:$C$3053,$B16) | J16: =IFERROR($I16/$H16,"") | K16: =SUMIFS(Factures!$M$2:$M$1085,Factures!$AD$2:$AD$1085,$B16)
B17: 2023-03 | C17: =SUMIFS(Factures!$K$2:$K$1085,Factures!$G$2:$G$1085,$B17) | D17: =SUMIFS(Factures!$U$2:$U$1085,Factures!$G$2:$G$1085,$B17) | E17: =$C17-$D17 | F17: =IFERROR($E17/$C17,"") | G17: =SUMIFS(Devis!$M$2:$M$3053,Devis!$C$2:$C$3053,$B17) | H17: =SUMIFS(Devis!$Y$2:$Y$3053,Devis!$C$2:$C$3053,$B17) | I17: =SUMIFS(Devis!$X$2:$X$3053,Devis!$C$2:$C$3053,$B17) | J17: =IFERROR($I17/$H17,"") | K17: =SUMIFS(Factures!$M$2:$M$1085,Factures!$AD$2:$AD$1085,$B17)
B18: 2023-04 | C18: =SUMIFS(Factures!$K$2:$K$1085,Factures!$G$2:$G$1085,$B18) | D18: =SUMIFS(Factures!$U$2:$U$1085,Factures!$G$2:$G$1085,$B18) | E18: =$C18-$D18 | F18: =IFERROR($E18/$C18,"") | G18: =SUMIFS(Devis!$M$2:$M$3053,Devis!$C$2:$C$3053,$B18) | H18: =SUMIFS(Devis!$Y$2:$Y$3053,Devis!$C$2:$C$3053,$B18) | I18: =SUMIFS(Devis!$X$2:$X$3053,Devis!$C$2:$C$3053,$B18) | J18: =IFERROR($I18/$H18,"") | K18: =SUMIFS(Factures!$M$2:$M$1085,Factures!$AD$2:$AD$1085,$B18)
B19: 2023-05 | C19: =SUMIFS(Factures!$K$2:$K$1085,Factures!$G$2:$G$1085,$B19) | D19: =SUMIFS(Factures!$U$2:$U$1085,Factures!$G$2:$G$1085,$B19) | E19: =$C19-$D19 | F19: =IFERROR($E19/$C19,"") | G19: =SUMIFS(Devis!$M$2:$M$3053,Devis!$C$2:$C$3053,$B19) | H19: =SUMIFS(Devis!$Y$2:$Y$3053,Devis!$C$2:$C$3053,$B19) | I19: =SUMIFS(Devis!$X$2:$X$3053,Devis!$C$2:$C$3053,$B19) | J19: =IFERROR($I19/$H19,"") | K19: =SUMIFS(Factures!$M$2:$M$1085,Factures!$AD$2:$AD$1085,$B19)
B20: 2023-06 | C20: =SUMIFS(Factures!$K$2:$K$1085,Factures!$G$2:$G$1085,$B20) | D20: =SUMIFS(Factures!$U$2:$U$1085,Factures!$G$2:$G$1085,$B20) | E20: =$C20-$D20 | F20: =IFERROR($E20/$C20,"") | G20: =SUMIFS(Devis!$M$2:$M$3053,Devis!$C$2:$C$3053,$B20) | H20: =SUMIFS(Devis!$Y$2:$Y$3053,Devis!$C$2:$C$3053,$B20) | I20: =SUMIFS(Devis!$X$2:$X$3053,Devis!$C$2:$C$3053,$B20) | J20: =IFERROR($I20/$H20,"") | K20: =SUMIFS(Factures!$M$2:$M$1085,Factures!$AD$2:$AD$1085,$B20)
... B56: 2026-06 | C56: =SUMIFS(Factures!$K$2:$K$1085,Factures!$G$2:$G$1085,$B56) | D56: =SUMIFS(Factures!$U$2:$U$1085,Factures!$G$2:$G$1085,$B56) | E56: =$C56-$D56 | F56: =IFERROR($E56/$C56,"") | G56: =SUMIFS(Devis!$M$2:$M$3053,Devis!$C$2:$C$3053,$B56) | H56: =SUMIFS(Devis!$Y$2:$Y$3053,Devis!$C$2:$C$3053,$B56) | I56: =SUMIFS(Devis!$X$2:$X$3053,Devis!$C$2:$C$3053,$B56) | J56: =IFERROR($I56/$H56,"") | K56: =SUMIFS(Factures!$M$2:$M$1085,Factures!$AD$2:$AD$1085,$B56)
B57: Total | C57: =SUM(C9:C56) | D57: =SUM(D9:D56) | E57: =$C57-$D57 | F57: =IFERROR($E57/$C57,"") | G57: =SUM(G9:G56) | H57: =SUM(H9:H56) | I57: =SUM(I9:I56) | J57: =IFERROR($I57/$H57,"") | K57: =SUM($K9:$K56)

Sheet Ce qui a été regardé
B2: B Â T I - S U D · G R O U P E A R T I S A N A L
B3: Ce qui a été regardé | G3: Traçabilité
B4: 23 croisements examinés, 21 recevables, 2 écartés avant scoring.
B7: Candidats les mieux placés
B8: Croisement | C8: Matérialité (€/an) | D8: Dispersion | E8: Stabilité | F8: Monotonie | G8: Score | H8: Retenu
B9: Panier moyen d'un devis gagné par type de client | C9: 83284.471 | D9: 0.29979548 | E9: 0.98360075 | F9: 0 | G9: 0.717531 | H9: oui
B10: Panier moyen d'un devis gagné par agence | C10: 47840.362 | D10: 0.34524803 | E10: 0.98797028 | F10: 0 | G10: 0.53763
B11: Taux de transformation des devis par agence | C11: 31811.189 | D11: 0.50586219 | E11: 0.99699684 | F11: 0 | G11: 0.490764 | H11: oui
B12: Taux de transformation des devis par type de client | C12: 26486.945 | D12: 0.44112778 | E12: 0.98929817 | F12: 0 | G12: 0.445166
B13: Taux de transformation des devis par métier | C13: 27335.282 | D13: 0.27782421 | E13: 0.91196824 | F13: 0 | G13: 0.395712
B14: Taux de marge brute par type de client | C14: 28135.787 | D14: 0.12647596 | E14: 0.95457206 | F14: 0 | G14: 0.37281
B15: Taux de transformation des devis par canal d'acquisition | C15: 16301.722 | D15: 0.35174154 | E15: 0.96010041 | F15: 0 | G15: 0.363181
B16: DSO — délai moyen d'encaissement par canal d'acquisition | D16: 0.6018258 | E16: 0.9549964 | F16: 0 | G16: 0.333149
B17: Taux de marge brute par métier | C17: 15754.907 | D17: 0.15274065 | E17: 0.91420419 | F17: 0 | G17: 0.304044
B18: Chiffre d'affaires facturé HT par métier | D18: 0.84674981 | E18: 0.5 | F18: 0 | G18: 0.3
B19: Taux de marge brute par agence | C19: 23175.911 | D19: 0.092748995 | E19: 0.74850414 | F19: 0 | G19: 0.296831
B20: Chiffre d'affaires facturé HT par agence | D20: 0.79845642 | E20: 0.5 | F20: 0 | G20: 0.288593
B22: Écartés avant scoring
B23: Croisement | C23: Motif
B24: Taux de marge brute par canal d'acquisition | C24: écart de 4.2%, sous le plancher de 5%
B25: DSO — délai moyen d'encaissement par type de client | C25: les modalités retenues ne couvrent que 70% du total
B27: Hypothèses explorées puis abandonnées
B28: Hypothèse | C28: Motif d'abandon
B29: Le taux de marge brute sur les Particuliers est structurellement plus faible que sur les autres clientèles. | C29: L'écart existe mais la mesure de marge brute est déjà couverte par le socle imposé, doublonner ferait perdre en lisibilité.
B30: Le taux de transformation sur Chauffage est dégradé et pèse sur l'ensemble de l'activité. | C30: L'écart est réel mais la Plomberie présente un niveau équivalent : aucun coupable métier isolé, donc aucune décision ciblée possible.
B31: Un effet combiné métier × agence existe sur la marge de la Salle de bain. | C31: Le croisement ne révèle aucune cellule Sala de bain × agence suffisamment peuplée et distinctive : l'hypothèse n'est pas démontrable.
B32: Le DSO dégradé provient du canal Site web, sur lequel le dirigeant peut agir. | C32: Confirmée mais la mesure DSO est déjà dans le socle imposé : pas un indicateur à choisir.

Sheet Paramètres
B2: B Â T I - S U D · G R O U P E A R T I S A N A L
B3: Paramètres, empreinte et méthode | H3: Feuille de contrôle
B4: Les cellules bleues sur fond jaune sont les seules à modifier.
B7: Paramètres de calcul
B8: Date de situation | C8: 46203 | D8: Référence de tous les calculs d'âge et de retard. La modifier recalcule le rapport.
B9: Début de la fenêtre | C9: =$C$8-364 | D9: Douze mois glissants.
B10: Fin de la fenêtre | C10: =$C$8
B11: Début de la comparaison | C11: =$C$8-729 | D11: Les douze mois précédents.
B12: Fin de la comparaison | C12: =$C$8-365
B13: Seuil de créance à risque | C13: 90 | D13: Ancienneté à partir de laquelle une créance passe en recouvrement.
B14: Délai de relance visé | C14: 3 | D14: Au-delà, le taux de transformation chute nettement.
B16: Conventions
B17: Bleu sur fond jaune | D17: Cellule de saisie — modifiable
B18: Noir | D18: Résultat de formule — ne pas écraser
B19: En-tête vert | D19: Colonne calculée ajoutée aux sources
B20: En-tête bleu nuit | D20: Donnée importée des CSV
B23: Empreinte du jeu de données
B24: Fichier | C24: Enregistrements | D24: SHA-256
B25: catalogue_prestations.csv | C25: 20 | D25: 40381635001b30885941e47a907d3c48…
B26: clients.csv | C26: 1019 | D26: 7d2022f6983fe3ef9d068227ddffd26c…
B27: devis.csv | C27: 3052 | D27: 0e8d4fbef0b01f2b8018e37d2bc59dad…
B28: factures.csv | C28: 1084 | D28: 7ab4af0426975929e48e5439f96db217…
B29: interventions.csv | C29: 1105 | D29: a9481f4482ad4f138bc242de79132086…
B30: relances.csv | C30: 3167 | D30: 74d3134700730081db2f02564b6be823…
B31: techniciens.csv | C31: 12 | D31: 743fdfd49eb2407bf9113c567686ccc7…
B32: Ensemble | C32: 9459 | D32: 2660 77f0 91a1 3a48 8501 45d4 c652 c30d
B34: Méthode
B35: • JEU DE DONNÉES FICTIF, généré pour démonstration. Aucune donnée réelle.
B36: • Période couverte : quatre exercices. Fenêtre d'analyse : exercice 2025-2026.
B37: • Le chiffre d'affaires est hors taxes ; l'encours en TTC, montant réellement dû.
B38: • Le coût de revient d'une facture est celui de l'intervention liée : heures réelles fois coût horaire du technicien, plus matériel. Aucun frais de structure.
B39: • La marge est donc une marge sur coûts directs, et non un résultat d'exploitation.
B40: • Les taux somment numérateurs et dénominateurs AVANT de diviser. La moyenne de trois taux de marge n'est pas le taux de marge de trois agences.
B41: • L'encours et le DSO sont des états à la date de situation : ils n'ont pas de version « période précédente », et aucune variation n'est affichée pour eux.
B42: • L'empreinte établit que le rapport porte sur ces fichiers exacts. Elle n'établit aucune antériorité : il y faudrait un horodatage par un tiers.
B43: • Toutes les cellules chiffrées sont des formules. Corriger une donnée source met à jour l'ensemble du rapport.

Sheet Devis
A1: Devis id | B1: Date emission | C1: Mois | D1: Exercice | E1: Client id | F1: Type client | G1: Agence | H1: Commercial | I1: Categorie | J1: Code prestation | K1: Libelle prestation | L1: Quantite | M1: Montant ht | N1: Statut | O1: Date decision | P1: Delai 1ere relance j | Q1: Nb relances | R1: Métier | S1: Prestation | T1: Canal d'acquisition | U1: Profil de paiement | V1: Ligne | W1: Gagné | X1: CA gagné HT | Y1: Montant arbitré HT | Z1: Relancé | AA1: Délai relance pondéré | AB1: Relance sous seuil | AC1: Tranche de relance | AD1: Tranche de montant
A2: DEV-00001 | B2: 44743 | C2: 2022-07 | D2: 2022-2023 | E2: CLI-0170 | F2: Particulier | G2: Toulouse | H2: Julien Fabre | I2: Plomberie | J2: PR-003 | K2: Réfection réseau eau appartement | L2: 1 | M2: 3434.79 | N2: Sans réponse | O2: 44770 | P2: 4 | Q2: 2 | R2: =$I2 | S2: =$K2 | T2: =IFERROR(INDEX(Clients!$G$2:$G$1020,MATCH($E2,Clients!$A$2:$A$1020,0)),"") | U2: =IFERROR(INDEX(Clients!$I$2:$I$1020,MATCH($E2,Clients!$A$2:$A$1020,0)),"") | V2: =1 | W2: =IF($N2="Accepté",1,0) | X2: =$M2*$W2 | Y2: =IF($N2="En cours",0,$M2) | Z2: =IF($P2="",0,1) | AA2: =IF($P2="",0,$P2) | AB2: =IF(AND($P2<>"",$P2<=Paramètres!$C$14),1,0) | AC2: =IF($P2="","Jamais relancé",IF($P2<=3,"0-3 j",IF($P2<=7,"4-7 j",IF($P2<=15,"8-15 j","Plus de 15 j")))) | AD2: =IF($M2<=1000,"Moins de 1 k€",IF($M2<=5000,"1 à 5 k€",IF($M2<=15000,"5 à 15 k€","Plus de 15 k€")))
A3: DEV-00002 | B3: 44743 | C3: 2022-07 | D3: 2022-2023 | E3: CLI-0150 | F3: Particulier | G3: Bordeaux | H3: Sophie Marchand | I3: Plomberie | J3: PR-002 | K3: Recherche de fuite + réparation | L3: 1 | M3: 420.94 | N3: Refusé | O3: 44746 | P3: 1 | Q3: 1 | R3: =$I3 | S3: =$K3 | T3: =IFERROR(INDEX(Clients!$G$2:$G$1020,MATCH($E3,Clients!$A$2:$A$1020,0)),"") | U3: =IFERROR(INDEX(Clients!$I$2:$I$1020,MATCH($E3,Clients!$A$2:$A$1020,0)),"") | V3: =1 | W3: =IF($N3="Accepté",1,0) | X3: =$M3*$W3 | Y3: =IF($N3="En cours",0,$M3) | Z3: =IF($P3="",0,1) | AA3: =IF($P3="",0,$P3) | AB3: =IF(AND($P3<>"",$P3<=Paramètres!$C$14),1,0) | AC3: =IF($P3="","Jamais relancé",IF($P3<=3,"0-3 j",IF($P3<=7,"4-7 j",IF($P3<=15,"8-15 j","Plus de 15 j")))) | AD3: =IF($M3<=1000,"Moins de 1 k€",IF($M3<=5000,"1 à 5 k€",IF($M3<=15000,"5 à 15 k€","Plus de 15 k€")))
A4: DEV-00003 | B4: 44743 | C4: 2022-07 | D4: 2022-2023 | E4: CLI-0145 | F4: Collectivité | G4: Bordeaux | H4: Karim Belkacem | I4: Salle de bain | J4: SB-001 | K4: Rénovation salle de bain complète | L4: 1 | M4: 20469.82 | N4: Refusé | O4: 44754 | Q4: 0 | R4: =$I4 | S4: =$K4 | T4: =IFERROR(INDEX(Clients!$G$2:$G$1020,MATCH($E4,Clients!$A$2:$A$1020,0)),"") | U4: =IFERROR(INDEX(Clients!$I$2:$I$1020,MATCH($E4,Clients!$A$2:$A$1020,0)),"") | V4: =1 | W4: =IF($N4="Accepté",1,0) | X4: =$M4*$W4 | Y4: =IF($N4="En cours",0,$M4) | Z4: =IF($P4="",0,1) | AA4: =IF($P4="",0,$P4) | AB4: =IF(AND($P4<>"",$P4<=Paramètres!$C$14),1,0) | AC4: =IF($P4="","Jamais relancé",IF($P4<=3,"0-3 j",IF($P4<=7,"4-7 j",IF($P4<=15,"8-15 j","Plus de 15 j")))) | AD4: =IF($M4<=1000,"Moins de 1 k€",IF($M4<=5000,"1 à 5 k€",IF($M4<=15000,"5 à 15 k€","Plus de 15 k€")))
A5: DEV-00004 | B5: 44746 | C5: 2022-07 | D5: 2022-2023 | E5: CLI-0120 | F5: Particulier | G5: Toulouse | H5: Julien Fabre | I5: Plomberie | J5: PR-003 | K5: Réfection réseau eau appartement | L5: 1 | M5: 2836.66 | N5: Refusé | O5: 44770 | P5: 10 | Q5: 2 | R5: =$I5 | S5: =$K5 | T5: =IFERROR(INDEX(Clients!$G$2:$G$1020,MATCH($E5,Clients!$A$2:$A$1020,0)),"") | U5: =IFERROR(INDEX(Clients!$I$2:$I$1020,MATCH($E5,Clients!$A$2:$A$1020,0)),"") | V5: =1 | W5: =IF($N5="Accepté",1,0) | X5: =$M5*$W5 | Y5: =IF($N5="En cours",0,$M5) | Z5: =IF($P5="",0,1) | AA5: =IF($P5="",0,$P5) | AB5: =IF(AND($P5<>"",$P5<=Paramètres!$C$14),1,0) | AC5: =IF($P5="","Jamais relancé",IF($P5<=3,"0-3 j",IF($P5<=7,"4-7 j",IF($P5<=15,"8-15 j","Plus de 15 j")))) | AD5: =IF($M5<=1000,"Moins de 1 k€",IF($M5<=5000,"1 à 5 k€",IF($M5<=15000,"5 à 15 k€","Plus de 15 k€")))
A6: DEV-00005 | B6: 44747 | C6: 2022-07 | D6: 2022-2023 | E6: CLI-0004 | F6: Particulier | G6: Bordeaux | H6: Karim Belkacem | I6: Chauffage | J6: CH-003 | K6: Installation pompe à chaleur air/eau | L6: 1 | M6: 13409.78 | N6: Refusé | O6: 44750 | P6: 9 | Q6: 0 | R6: =$I6 | S6: =$K6 | T6: =IFERROR(INDEX(Clients!$G$2:$G$1020,MATCH($E6,Clients!$A$2:$A$1020,0)),"") | U6: =IFERROR(INDEX(Clients!$I$2:$I$1020,MATCH($E6,Clients!$A$2:$A$1020,0)),"") | V6: =1 | W6: =IF($N6="Accepté",1,0) | X6: =$M6*$W6 | Y6: =IF($N6="En cours",0,$M6) | Z6: =IF($P6="",0,1) | AA6: =IF($P6="",0,$P6) | AB6: =IF(AND($P6<>"",$P6<=Paramètres!$C$14),1,0) | AC6: =IF($P6="","Jamais relancé",IF($P6<=3,"0-3 j",IF($P6<=7,"4-7 j",IF($P6<=15,"8-15 j","Plus de 15 j")))) | AD6: =IF($M6<=1000,"Moins de 1 k€",IF($M6<=5000,"1 à 5 k€",IF($M6<=15000,"5 à 15 k€","Plus de 15 k€")))
A7: DEV-00006 | B7: 44747 | C7: 2022-07 | D7: 2022-2023 | E7: CLI-0114 | F7: Particulier | G7: Bordeaux | H7: Sophie Marchand | I7: Plomberie | J7: PR-002 | K7: Recherche de fuite + réparation | L7: 1 | M7: 408.99 | N7: Accepté | O7: 44759 | P7: 1 | Q7: 2 | R7: =$I7 | S7: =$K7 | T7: =IFERROR(INDEX(Clients!$G$2:$G$1020,MATCH($E7,Clients!$A$2:$A$1020,0)),"") | U7: =IFERROR(INDEX(Clients!$I$2:$I$1020,MATCH($E7,Clients!$A$2:$A$1020,0)),"") | V7: =1 | W7: =IF($N7="Accepté",1,0) | X7: =$M7*$W7 | Y7: =IF($N7="En cours",0,$M7) | Z7: =IF($P7="",0,1) | AA7: =IF($P7="",0,$P7) | AB7: =IF(AND($P7<>"",$P7<=Paramètres!$C$14),1,0) | AC7: =IF($P7="","Jamais relancé",IF($P7<=3,"0-3 j",IF($P7<=7,"4-7 j",IF($P7<=15,"8-15 j","Plus de 15 j")))) | AD7: =IF($M7<=1000,"Moins de 1 k€",IF($M7<=5000,"1 à 5 k€",IF($M7<=15000,"5 à 15 k€","Plus de 15 k€")))
A8: DEV-00007 | B8: 44748 | C8: 2022-07 | D8: 2022-2023 | E8: CLI-0068 | F8: Particulier | G8: Bordeaux | H8: Karim Belkacem | I8: Plomberie | J8: PR-001 | K8: Remplacement chauffe-eau 200 L | L8: 1 | M8: 1043.35 | N8: Refusé | O8: 44777 | P8: 1 | Q8: 1 | R8: =$I8 | S8: =$K8 | T8: =IFERROR(INDEX(Clients!$G$2:$G$1020,MATCH($E8,Clients!$A$2:$A$1020,0)),"") | U8: =IFERROR(INDEX(Clients!$I$2:$I$1020,MATCH($E8,Clients!$A$2:$A$1020,0)),"") | V8: =1 | W8: =IF($N8="Accepté",1,0) | X8: =$M8*$W8 | Y8: =IF($N8="En cours",0,$M8) | Z8: =IF($P8="",0,1) | AA8: =IF($P8="",0,$P8) | AB8: =IF(AND($P8<>"",$P8<=Paramètres!$C$14),1,0) | AC8: =IF($P8="","Jamais relancé",IF($P8<=3,"0-3 j",IF($P8<=7,"4-7 j",IF($P8<=15,"8-15 j","Plus de 15 j")))) | AD8: =IF($M8<=1000,"Moins de 1 k€",IF($M8<=5000,"1 à 5 k€",IF($M8<=15000,"5 à 15 k€","Plus de 15 k€")))
A9: DEV-00008 | B9: 44748 | C9: 2022-07 | D9: 2022-2023 | E9: CLI-0160 | F9: Particulier | G9: Bordeaux | H9: Karim Belkacem | I9: Plomberie | J9: PR-004 | K9: Remplacement colonne d'évacuation | L9: 1 | M9: 5812.36 | N9: Accepté | O9: 44780 | P9: 3 | Q9: 1 | R9: =$I9 | S9: =$K9 | T9: =IFERROR(INDEX(Clients!$G$2:$G$1020,MATCH($E9,Clients!$A$2:$A$1020,0)),"") | U9: =IFERROR(INDEX(Clients!$I$2:$I$1020,MATCH($E9,Clients!$A$2:$A$1020,0)),"") | V9: =1 | W9: =IF($N9="Accepté",1,0) | X9: =$M9*$W9 | Y9: =IF($N9="En cours",0,$M9) | Z9: =IF($P9="",0,1) | AA9: =IF($P9="",0,$P9) | AB9: =IF(AND($P9<>"",$P9<=Paramètres!$C$14),1,0) | AC9: =IF($P9="","Jamais relancé",IF($P9<=3,"0-3 j",IF($P9<=7,"4-7 j",IF($P9<=15,"8-15 j","Plus de 15 j")))) | AD9: =IF($M9<=1000,"Moins de 1 k€",IF($M9<=5000,"1 à 5 k€",IF($M9<=15000,"5 à 15 k€","Plus de 15 k€")))
A10: DEV-00009 | B10: 44748 | C10: 2022-07 | D10: 2022-2023 | E10: CLI-0102 | F10: Particulier | G10: Toulouse | H10: Julien Fabre | I10: Plomberie | J10: PR-002 | K10: Recherche de fuite + réparation | L10: 1 | M10: 420.81 | N10: Refusé | O10: 44770 | P10: 8 | Q10: 2 | R10: =$I10 | S10: =$K10 | T10: =IFERROR(INDEX(Clients!$G$2:$G$1020,MATCH($E10,Clients!$A$2:$A$1020,0)),"") | U10: =IFERROR(INDEX(Clients!$I$2:$I$1020,MATCH($E10,Clients!$A$2:$A$1020,0)),"") | V10: =1 | W10: =IF($N10="Accepté",1,0) | X10: =$M10*$W10 | Y10: =IF($N10="En cours",0,$M10) | Z10: =IF($P10="",0,1) | AA10: =IF($P10="",0,$P10) | AB10: =IF(AND($P10<>"",$P10<=Paramètres!$C$14),1,0) | AC10: =IF($P10="","Jamais relancé",IF($P10<=3,"0-3 j",IF($P10<=7,"4-7 j",IF($P10<=15,"8-15 j","Plus de 15 j")))) | AD10: =IF($M10<=1000,"Moins de 1 k€",IF($M10<=5000,"1 à 5 k€",IF($M10<=15000,"5 à 15 k€","Plus de 15 k€")))
A11: DEV-00010 | B11: 44750 | C11: 2022-07 | D11: 2022-2023 | E11: CLI-0089 | F11: Particulier | G11: Bordeaux | H11: Karim Belkacem | I11: Salle de bain | J11: SB-003 | K11: Pose meuble vasque + robinetterie | L11: 1 | M11: 1332.2 | N11: Accepté | O11: 44777 | P11: 1 | Q11: 3 | R11: =$I11 | S11: =$K11 | T11: =IFERROR(INDEX(Clients!$G$2:$G$1020,MATCH($E11,Clients!$A$2:$A$1020,0)),"") | U11: =IFERROR(INDEX(Clients!$I$2:$I$1020,MATCH($E11,Clients!$A$2:$A$1020,0)),"") | V11: =1 | W11: =IF($N11="Accepté",1,0) | X11: =$M11*$W11 | Y11: =IF($N11="En cours",0,$M11) | Z11: =IF($P11="",0,1) | AA11: =IF($P11="",0,$P11) | AB11: =IF(AND($P11<>"",$P11<=Paramètres!$C$14),1,0) | AC11: =IF($P11="","Jamais relancé",IF($P11<=3,"0-3 j",IF($P11<=7,"4-7 j",IF($P11<=15,"8-15 j","Plus de 15 j")))) | AD11: =IF($M11<=1000,"Moins de 1 k€",IF($M11<=5000,"1 à 5 k€",IF($M11<=15000,"5 à 15 k€","Plus de 15 k€")))
A12: DEV-00011 | B12: 44750 | C12: 2022-07 | D12: 2022-2023 | E12: CLI-0043 | F12: Particulier | G12: Toulouse | H12: Julien Fabre | I12: Salle de bain | J12: SB-001 | K12: Rénovation salle de bain complète | L12: 1 | M12: 9816.44 | N12: Sans réponse | O12: 44754 | P12: 5 | Q12: 0 | R12: =$I12 | S12: =$K12 | T12: =IFERROR(INDEX(Clients!$G$2:$G$1020,MATCH($E12,Clients!$A$2:$A$1020,0)),"") | U12: =IFERROR(INDEX(Clients!$I$2:$I$1020,MATCH($E12,Clients!$A$2:$A$1020,0)),"") | V12: =1 | W12: =IF($N12="Accepté",1,0) | X12: =$M12*$W12 | Y12: =IF($N12="En cours",0,$M12) | Z12: =IF($P12="",0,1) | AA12: =IF($P12="",0,$P12) | AB12: =IF(AND($P12<>"",$P12<=Paramètres!$C$14),1,0) | AC12: =IF($P12="","Jamais relancé",IF($P12<=3,"0-3 j",IF($P12<=7,"4-7 j",IF($P12<=15,"8-15 j","Plus de 15 j")))) | AD12: =IF($M12<=1000,"Moins de 1 k€",IF($M12<=5000,"1 à 5 k€",IF($M12<=15000,"5 à 15 k€","Plus de 15 k€")))
A13: DEV-00012 | B13: 44753 | C13: 2022-07 | D13: 2022-2023 | E13: CLI-0151 | F13: Syndic | G13: Bordeaux | H13: Karim Belkacem | I13: Salle de bain | J13: SB-002 | K13: Remplacement baignoire par douche | L13: 1 | M13: 7815.09 | N13: Refusé | O13: 44780 | Q13: 0 | R13: =$I13 | S13: =$K13 | T13: =IFERROR(INDEX(Clients!$G$2:$G$1020,MATCH($E13,Clients!$A$2:$A$1020,0)),"") | U13: =IFERROR(INDEX(Clients!$I$2:$I$1020,MATCH($E13,Clients!$A$2:$A$1020,0)),"") | V13: =1 | W13: =IF($N13="Accepté",1,0) | X13: =$M13*$W13 | Y13: =IF($N13="En cours",0,$M13) | Z13: =IF($P13="",0,1) | AA13: =IF($P13="",0,$P13) | AB13: =IF(AND($P13<>"",$P13<=Paramètres!$C$14),1,0) | AC13: =IF($P13="","Jamais relancé",IF($P13<=3,"0-3 j",IF($P13<=7,"4-7 j",IF($P13<=15,"8-15 j","Plus de 15 j")))) | AD13: =IF($M13<=1000,"Moins de 1 k€",IF($M13<=5000,"1 à 5 k€",IF($M13<=15000,"5 à 15 k€","Plus de 15 k€")))
A14: DEV-00013 | B14: 44753 | C14: 2022-07 | D14: 2022-2023 | E14: CLI-0051 | F14: Particulier | G14: Toulouse | H14: Julien Fabre | I14: Salle de bain | J14: SB-001 | K14: Rénovation salle de bain complète | L14: 1 | M14: 8570.48 | N14: Refusé | O14: 44781 | P14: 1 | Q14: 1 | R14: =$I14 | S14: =$K14 | T14: =IFERROR(INDEX(Clients!$G$2:$G$1020,MATCH($E14,Clients!$A$2:$A$1020,0)),"") | U14: =IFERROR(INDEX(Clients!$I$2:$I$1020,MATCH($E14,Clients!$A$2:$A$1020,0)),"") | V14: =1 | W14: =IF($N14="Accepté",1,0) | X14: =$M14*$W14 | Y14: =IF($N14="En cours",0,$M14) | Z14: =IF($P14="",0,1) | AA14: =IF($P14="",0,$P14) | AB14: =IF(AND($P14<>"",$P14<=Paramètres!$C$14),1,0) | AC14: =IF($P14="","Jamais relancé",IF($P14<=3,"0-3 j",IF($P14<=7,"4-7 j",IF($P14<=15,"8-15 j","Plus de 15 j")))) | AD14: =IF($M14<=1000,"Moins de 1 k€",IF($M14<=5000,"1 à 5 k€",IF($M14<=15000,"5 à 15 k€","Plus de 15 k€")))
A15: DEV-00014 | B15: 44753 | C15: 2022-07 | D15: 2022-2023 | E15: CLI-0098 | F15: Particulier | G15: Bordeaux | H15: Karim Belkacem | I15: Dépannage | J15: DP-004 | K15: Remise en service chaudière | L15: 1 | M15: 223.45 | N15: Accepté | O15: 44772 | P15: 2 | Q15: 1 | R15: =$I15 | S15: =$K15 | T15: =IFERROR(INDEX(Clients!$G$2:$G$1020,MATCH($E15,Clients!$A$2:$A$1020,0)),"") | U15: =IFERROR(INDEX(Clients!$I$2:$I$1020,MATCH($E15,Clients!$A$2:$A$1020,0)),"") | V15: =1 | W15: =IF($N15="Accepté",1,0) | X15: =$M15*$W15 | Y15: =IF($N15="En cours",0,$M15) | Z15: =IF($P15="",0,1) | AA15: =IF($P15="",0,$P15) | AB15: =IF(AND($P15<>"",$P15<=Paramètres!$C$14),1,0) | AC15: =IF($P15="","Jamais relancé",IF($P15<=3,"0-3 j",IF($P15<=7,"4-7 j",IF($P15<=15,"8-15 j","Plus de 15 j")))) | AD15: =IF($M15<=1000,"Moins de 1 k€",IF($M15<=5000,"1 à 5 k€",IF($M15<=15000,"5 à 15 k€","Plus de 15 k€")))
A16: DEV-00015 | B16: 44754 | C16: 2022-07 | D16: 2022-2023 | E16: CLI-0042 | F16: Particulier | G16: Bordeaux | H16: Sophie Marchand | I16: Dépannage | J16: DP-002 | K16: Débouchage canalisation | L16: 1 | M16: 331.48 | N16: Accepté | O16: 44762 | P16: 3 | Q16: 1 | R16: =$I16 | S16: =$K16 | T16: =IFERROR(INDEX(Clients!$G$2:$G$1020,MATCH($E16,Clients!$A$2:$A$1020,0)),"") | U16: =IFERROR(INDEX(Clients!$I$2:$I$1020,MATCH($E16,Clients!$A$2:$A$1020,0)),"") | V16: =1 | W16: =IF($N16="Accepté",1,0) | X16: =$M16*$W16 | Y16: =IF($N16="En cours",0,$M16) | Z16: =IF($P16="",0,1) | AA16: =IF($P16="",0,$P16) | AB16: =IF(AND($P16<>"",$P16<=Paramètres!$C$14),1,0) | AC16: =IF($P16="","Jamais relancé",IF($P16<=3,"0-3 j",IF($P16<=7,"4-7 j",IF($P16<=15,"8-15 j","Plus de 15 j")))) | AD16: =IF($M16<=1000,"Moins de 1 k€",IF($M16<=5000,"1 à 5 k€",IF($M16<=15000,"5 à 15 k€","Plus de 15 k€")))
A17: DEV-00016 | B17: 44754 | C17: 2022-07 | D17: 2022-2023 | E17: CLI-0049 | F17: Particulier | G17: Bordeaux | H17: Karim Belkacem | I17: Chauffage | J17: CH-005 | K17: Désembouage circuit chauffage | L17: 1 | M17: 730.54 | N17: Sans réponse | O17: 44774 | P17: 6 | Q17: 1 | R17: =$I17 | S17: =$K17 | T17: =IFERROR(INDEX(Clients!$G$2:$G$1020,MATCH($E17,Clients!$A$2:$A$1020,0)),"") | U17: =IFERROR(INDEX(Clients!$I$2:$I$1020,MATCH($E17,Clients!$A$2:$A$1020,0)),"") | V17: =1 | W17: =IF($N17="Accepté",1,0) | X17: =$M17*$W17 | Y17: =IF($N17="En cours",0,$M17) | Z17: =IF($P17="",0,1) | AA17: =IF($P17="",0,$P17) | AB17: =IF(AND($P17<>"",$P17<=Paramètres!$C$14),1,0) | AC17: =IF($P17="","Jamais relancé",IF($P17<=3,"0-3 j",IF($P17<=7,"4-7 j",IF($P17<=15,"8-15 j","Plus de 15 j")))) | AD17: =IF($M17<=1000,"Moins de 1 k€",IF($M17<=5000,"1 à 5 k€",IF($M17<=15000,"5 à 15 k€","Plus de 15 k€")))
A18: DEV-00017 | B18: 44754 | C18: 2022-07 | D18: 2022-2023 | E18: CLI-0083 | F18: Collectivité | G18: Toulouse | H18: Julien Fabre | I18: Salle de bain | J18: SB-001 | K18: Rénovation salle de bain complète | L18: 1 | M18: 25587.26 | N18: Sans réponse | O18: 44770 | P18: 10 | Q18: 1 | R18: =$I18 | S18: =$K18 | T18: =IFERROR(INDEX(Clients!$G$2:$G$1020,MATCH($E18,Clients!$A$2:$A$1020,0)),"") | U18: =IFERROR(INDEX(Clients!$I$2:$I$1020,MATCH($E18,Clients!$A$2:$A$1020,0)),"") | V18: =1 | W18: =IF($N18="Accepté",1,0) | X18: =$M18*$W18 | Y18: =IF($N18="En cours",0,$M18) | Z18: =IF($P18="",0,1) | AA18: =IF($P18="",0,$P18) | AB18: =IF(AND($P18<>"",$P18<=Paramètres!$C$14),1,0) | AC18: =IF($P18="","Jamais relancé",IF($P18<=3,"0-3 j",IF($P18<=7,"4-7 j",IF($P18<=15,"8-15 j","Plus de 15 j")))) | AD18: =IF($M18<=1000,"Moins de 1 k€",IF($M18<=5000,"1 à 5 k€",IF($M18<=15000,"5 à 15 k€","Plus de 15 k€")))
A19: DEV-00018 | B19: 44755 | C19: 2022-07 | D19: 2022-2023 | E19: CLI-0079 | F19: Particulier | G19: Bordeaux | H19: Karim Belkacem | I19: Électricité | J19: EL-004 | K19: Éclairage LED locaux professionnels | L19: 1 | M19: 3374.26 | N19: Refusé | O19: 44777 | P19: 7 | Q19: 2 | R19: =$I19 | S19: =$K19 | T19: =IFERROR(INDEX(Clients!$G$2:$G$1020,MATCH($E19,Clients!$A$2:$A$1020,0)),"") | U19: =IFERROR(INDEX(Clients!$I$2:$I$1020,MATCH($E19,Clients!$A$2:$A$1020,0)),"") | V19: =1 | W19: =IF($N19="Accepté",1,0) | X19: =$M19*$W19 | Y19: =IF($N19="En cours",0,$M19) | Z19: =IF($P19="",0,1) | AA19: =IF($P19="",0,$P19) | AB19: =IF(AND($P19<>"",$P19<=Paramètres!$C$14),1,0) | AC19: =IF($P19="","Jamais relancé",IF($P19<=3,"0-3 j",IF($P19<=7,"4-7 j",IF($P19<=15,"8-15 j","Plus de 15 j")))) | AD19: =IF($M19<=1000,"Moins de 1 k€",IF($M19<=5000,"1 à 5 k€",IF($M19<=15000,"5 à 15 k€","Plus de 15 k€")))
A20: DEV-00019 | B20: 44755 | C20: 2022-07 | D20: 2022-2023 | E20: CLI-0168 | F20: Particulier | G20: Bordeaux | H20: Karim Belkacem | I20: Plomberie | J20: PR-004 | K20: Remplacement colonne d'évacuation | L20: 1 | M20: 5021.61 | N20: Sans réponse | O20: 44772 | Q20: 0 | R20: =$I20 | S20: =$K20 | T20: =IFERROR(INDEX(Clients!$G$2:$G$1020,MATCH($E20,Clients!$A$2:$A$1020,0)),"") | U20: =IFERROR(INDEX(Clients!$I$2:$I$1020,MATCH($E20,Clients!$A$2:$A$1020,0)),"") | V20: =1 | W20: =IF($N20="Accepté",1,0) | X20: =$M20*$W20 | Y20: =IF($N20="En cours",0,$M20) | Z20: =IF($P20="",0,1) | AA20: =IF($P20="",0,$P20) | AB20: =IF(AND($P20<>"",$P20<=Paramètres!$C$14),1,0) | AC20: =IF($P20="","Jamais relancé",IF($P20<=3,"0-3 j",IF($P20<=7,"4-7 j",IF($P20<=15,"8-15 j","Plus de 15 j")))) | AD20: =IF($M20<=1000,"Moins de 1 k€",IF($M20<=5000,"1 à 5 k€",IF($M20<=15000,"5 à 15 k€","Plus de 15 k€")))
A21: DEV-00020 | B21: 44757 | C21: 2022-07 | D21: 2022-2023 | E21: CLI-0133 | F21: Syndic | G21: Bordeaux | H21: Sophie Marchand | I21: Dépannage | J21: DP-002 | K21: Débouchage canalisation | L21: 1 | M21: 737.31 | N21: Refusé | O21: 44790 | P21: 8 | Q21: 2 | R21: =$I21 | S21: =$K21 | T21: =IFERROR(INDEX(Clients!$G$2:$G$1020,MATCH($E21,Clients!$A$2:$A$1020,0)),"") | U21: =IFERROR(INDEX(Clients!$I$2:$I$1020,MATCH($E21,Clients!$A$2:$A$1020,0)),"") | V21: =1 | W21: =IF($N21="Accepté",1,0) | X21: =$M21*$W21 | Y21: =IF($N21="En cours",0,$M21) | Z21: =IF($P21="",0,1) | AA21: =IF($P21="",0,$P21) | AB21: =IF(AND($P21<>"",$P21<=Paramètres!$C$14),1,0) | AC21: =IF($P21="","Jamais relancé",IF($P21<=3,"0-3 j",IF($P21<=7,"4-7 j",IF($P21<=15,"8-15 j","Plus de 15 j")))) | AD21: =IF($M21<=1000,"Moins de 1 k€",IF($M21<=5000,"1 à 5 k€",IF($M21<=15000,"5 à 15 k€","Plus de 15 k€")))
A22: DEV-00021 | B22: 44757 | C22: 2022-07 | D22: 2022-2023 | E22: CLI-0056 | F22: Particulier | G22: Bordeaux | H22: Sophie Marchand | I22: Plomberie | J22: PR-002 | K22: Recherche de fuite + réparation | L22: 1 | M22: 491.43 | N22: Sans réponse | O22: 44765 | P22: 9 | Q22: 0 | R22: =$I22 | S22: =$K22 | T22: =IFERROR(INDEX(Clients!$G$2:$G$1020,MATCH($E22,Clients!$A$2:$A$1020,0)),"") | U22: =IFERROR(INDEX(Clients!$I$2:$I$1020,MATCH($E22,Clients!$A$2:$A$1020,0)),"") | V22: =1 | W22: =IF($N22="Accepté",1,0) | X22: =$M22*$W22 | Y22: =IF($N22="En cours",0,$M22) | Z22: =IF($P22="",0,1) | AA22: =IF($P22="",0,$P22) | AB22: =IF(AND($P22<>"",$P22<=Paramètres!$C$14),1,0) | AC22: =IF($P22="","Jamais relancé",IF($P22<=3,"0-3 j",IF($P22<=7,"4-7 j",IF($P22<=15,"8-15 j","Plus de 15 j")))) | AD22: =IF($M22<=1000,"Moins de 1 k€",IF($M22<=5000,"1 à 5 k€",IF($M22<=15000,"5 à 15 k€","Plus de 15 k€")))
A23: DEV-00022 | B23: 44757 | C23: 2022-07 | D23: 2022-2023 | E23: CLI-0014 | F23: Particulier | G23: Bordeaux | H23: Karim Belkacem | I23: Plomberie | J23: PR-003 | K23: Réfection réseau eau appartement | L23: 1 | M23: 3207.71 | N23: Sans réponse | O23: 44769 | P23: 4 | Q23: 2 | R23: =$I23 | S23: =$K23 | T23: =IFERROR(INDEX(Clients!$G$2:$G$1020,MATCH($E23,Clients!$A$2:$A$1020,0)),"") | U23: =IFERROR(INDEX(Clients!$I$2:$I$1020,MATCH($E23,Clients!$A$2:$A$1020,0)),"") | V23: =1 | W23: =IF($N23="Accepté",1,0) | X23: =$M23*$W23 | Y23: =IF($N23="En cours",0,$M23) | Z23: =IF($P23="",0,1) | AA23: =IF($P23="",0,$P23) | AB23: =IF(AND($P23<>"",$P23<=Paramètres!$C$14),1,0) | AC23: =IF($P23="","Jamais relancé",IF($P23<=3,"0-3 j",IF($P23<=7,"4-7 j",IF($P23<=15,"8-15 j","Plus de 15 j")))) | AD23: =IF($M23<=1000,"Moins de 1 k€",IF($M23<=5000,"1 à 5 k€",IF($M23<=15000,"5 à 15 k€","Plus de 15 k€")))
A24: DEV-00023 | B24: 44760 | C24: 2022-07 | D24: 2022-2023 | E24: CLI-0061 | F24: Professionnel | G24: Toulouse | H24: Julien Fabre | I24: Électricité | J24: EL-002 | K24: Installation borne de recharge VE | L24: 1 | M24: 2265.82 | N24: Sans réponse | O24: 44798 | P24: 3 | Q24: 3 | R24: =$I24 | S24: =$K24 | T24: =IFERROR(INDEX(Clients!$G$2:$G$1020,MATCH($E24,Clients!$A$2:$A$1020,0)),"") | U24: =IFERROR(INDEX(Clients!$I$2:$I$1020,MATCH($E24,Clients!$A$2:$A$1020,0)),"") | V24: =1 | W24: =IF($N24="Accepté",1,0) | X24: =$M24*$W24 | Y24: =IF($N24="En cours",0,$M24) | Z24: =IF($P24="",0,1) | AA24: =IF($P24="",0,$P24) | AB24: =IF(AND($P24<>"",$P24<=Paramètres!$C$14),1,0) | AC24: =IF($P24="","Jamais relancé",IF($P24<=3,"0-3 j",IF($P24<=7,"4-7 j",IF($P24<=15,"8-15 j","Plus de 15 j")))) | AD24: =IF($M24<=1000,"Moins de 1 k€",IF($M24<=5000,"1 à 5 k€",IF($M24<=15000,"5 à 15 k€","Plus de 15 k€")))
A25: DEV-00024 | B25: 44762 | C25: 2022-07 | D25: 2022-2023 | E25: CLI-0026 | F25: Particulier | G25: Bordeaux | H25: Sophie Marchand | I25: Salle de bain | J25: SB-001 | K25: Rénovation salle de bain complète | L25: 1 | M25: 10132.95 | N25: Sans réponse | O25: 44806 | P25: 12 | Q25: 1 | R25: =$I25 | S25: =$K25 | T25: =IFERROR(INDEX(Clients!$G$2:$G$1020,MATCH($E25,Clients!$A$2:$A$1020,0)),"") | U25: =IFERROR(INDEX(Clients!$I$2:$I$1020,MATCH($E25,Clients!$A$2:$A$1020,0)),"") | V25: =1 | W25: =IF($N25="Accepté",1,0) | X25: =$M25*$W25 | Y25: =IF($N25="En cours",0,$M25) | Z25: =IF($P25="",0,1) | AA25: =IF($P25="",0,$P25) | AB25: =IF(AND($P25<>"",$P25<=Paramètres!$C$14),1,0) | AC25: =IF($P25="","Jamais relancé",IF($P25<=3,"0-3 j",IF($P25<=7,"4-7 j",IF($P25<=15,"8-15 j","Plus de 15 j")))) | AD25: =IF($M25<=1000,"Moins de 1 k€",IF($M25<=5000,"1 à 5 k€",IF($M25<=15000,"5 à 15 k€","Plus de 15 k€")))
A26: DEV-00025 | B26: 44763 | C26: 2022-07 | D26: 2022-2023 | E26: CLI-0002 | F26: Particulier | G26: Bordeaux | H26: Sophie Marchand | I26: Dépannage | J26: DP-003 | K26: Dépannage électrique urgence | L26: 1 | M26: 311.16 | N26: Sans réponse | O26: 44787 | Q26: 0 | R26: =$I26 | S26: =$K26 | T26: =IFERROR(INDEX(Clients!$G$2:$G$1020,MATCH($E26,Clients!$A$2:$A$1020,0)),"") | U26: =IFERROR(INDEX(Clients!$I$2:$I$1020,MATCH($E26,Clients!$A$2:$A$1020,0)),"") | V26: =1 | W26: =IF($N26="Accepté",1,0) | X26: =$M26*$W26 | Y26: =IF($N26="En cours",0,$M26) | Z26: =IF($P26="",0,1) | AA26: =IF($P26="",0,$P26) | AB26: =IF(AND($P26<>"",$P26<=Paramètres!$C$14),1,0) | AC26: =IF($P26="","Jamais relancé",IF($P26<=3,"0-3 j",IF($P26<=7,"4-7 j",IF($P26<=15,"8-15 j","Plus de 15 j")))) | AD26: =IF($M26<=1000,"Moins de 1 k€",IF($M26<=5000,"1 à 5 k€",IF($M26<=15000,"5 à 15 k€","Plus de 15 k€")))
A27: DEV-00026 | B27: 44763 | C27: 2022-07 | D27: 2022-2023 | E27: CLI-0156 | F27: Particulier | G27: Bordeaux | H27: Karim Belkacem | I27: Plomberie | J27: PR-003 | K27: Réfection réseau eau appartement | L27: 1 | M27: 3476.87 | N27: Accepté | O27: 44786 | P27: 1 | Q27: 1 | R27: =$I27 | S27: =$K27 | T27: =IFERROR(INDEX(Clients!$G$2:$G$1020,MATCH($E27,Clients!$A$2:$A$1020,0)),"") | U27: =IFERROR(INDEX(Clients!$I$2:$I$1020,MATCH($E27,Clients!$A$2:$A$1020,0)),"") | V27: =1 | W27: =IF($N27="Accepté",1,0) | X27: =$M27*$W27 | Y27: =IF($N27="En cours",0,$M27) | Z27: =IF($P27="",0,1) | AA27: =IF($P27="",0,$P27) | AB27: =IF(AND($P27<>"",$P27<=Paramètres!$C$14),1,0) | AC27: =IF($P27="","Jamais relancé",IF($P27<=3,"0-3 j",IF($P27<=7,"4-7 j",IF($P27<=15,"8-15 j","Plus de 15 j")))) | AD27: =IF($M27<=1000,"Moins de 1 k€",IF($M27<=5000,"1 à 5 k€",IF($M27<=15000,"5 à 15 k€","Plus de 15 k€")))
A28: DEV-00027 | B28: 44763 | C28: 2022-07 | D28: 2022-2023 | E28: CLI-0094 | F28: Professionnel | G28: Toulouse | H28: Julien Fabre | I28: Électricité | J28: EL-003 | K28: Rénovation électrique complète | L28: 1 | M28: 16995.08 | N28: Sans réponse | O28: 44787 | P28: 6 | Q28: 3 | R28: =$I28 | S28: =$K28 | T28: =IFERROR(INDEX(Clients!$G$2:$G$1020,MATCH($E28,Clients!$A$2:$A$1020,0)),"") | U28: =IFERROR(INDEX(Clients!$I$2:$I$1020,MATCH($E28,Clients!$A$2:$A$1020,0)),"") | V28: =1 | W28: =IF($N28="Accepté",1,0) | X28: =$M28*$W28 | Y28: =IF($N28="En cours",0,$M28) | Z28: =IF($P28="",0,1) | AA28: =IF($P28="",0,$P28) | AB28: =IF(AND($P28<>"",$P28<=Paramètres!$C$14),1,0) | AC28: =IF($P28="","Jamais relancé",IF($P28<=3,"0-3 j",IF($P28<=7,"4-7 j",IF($P28<=15,"8-15 j","Plus de 15 j")))) | AD28: =IF($M28<=1000,"Moins de 1 k€",IF($M28<=5000,"1 à 5 k€",IF($M28<=15000,"5 à 15 k€","Plus de 15 k€")))
A29: DEV-00028 | B29: 44763 | C29: 2022-07 | D29: 2022-2023 | E29: CLI-0005 | F29: Particulier | G29: Bordeaux | H29: Sophie Marchand | I29: Dépannage | J29: DP-001 | K29: Dépannage plomberie urgence | L29: 1 | M29: 262.87 | N29: Accepté | O29: 44774 | P29: 2 | Q29: 1 | R29: =$I29 | S29: =$K29 | T29: =IFERROR(INDEX(Clients!$G$2:$G$1020,MATCH($E29,Clients!$A$2:$A$1020,0)),"") | U29: =IFERROR(INDEX(Clients!$I$2:$I$1020,MATCH($E29,Clients!$A$2:$A$1020,0)),"") | V29: =1 | W29: =IF($N29="Accepté",1,0) | X29: =$M29*$W29 | Y29: =IF($N29="En cours",0,$M29) | Z29: =IF($P29="",0,1) | AA29: =IF($P29="",0,$P29) | AB29: =IF(AND($P29<>"",$P29<=Paramètres!$C$14),1,0) | AC29: =IF($P29="","Jamais relancé",IF($P29<=3,"0-3 j",IF($P29<=7,"4-7 j",IF($P29<=15,"8-15 j","Plus de 15 j")))) | AD29: =IF($M29<=1000,"Moins de 1 k€",IF($M29<=5000,"1 à 5 k€",IF($M29<=15000,"5 à 15 k€","Plus de 15 k€")))
A30: DEV-00029 | B30: 44764 | C30: 2022-07 | D30: 2022-2023 | E30: CLI-0059 | F30: Particulier | G30: Bordeaux | H30: Karim Belkacem | I30: Électricité | J30: EL-001 | K30: Mise aux normes tableau électrique | L30: 1 | M30: 1839.23 | N30: Sans réponse | O30: 44804 | P30: 1 | Q30: 3 | R30: =$I30 | S30: =$K30 | T30: =IFERROR(INDEX(Clients!$G$2:$G$1020,MATCH($E30,Clients!$A$2:$A$1020,0)),"") | U30: =IFERROR(INDEX(Clients!$I$2:$I$1020,MATCH($E30,Clients!$A$2:$A$1020,0)),"") | V30: =1 | W30: =IF($N30="Accepté",1,0) | X30: =$M30*$W30 | Y30: =IF($N30="En cours",0,$M30) | Z30: =IF($P30="",0,1) | AA30: =IF($P30="",0,$P30) | AB30: =IF(AND($P30<>"",$P30<=Paramètres!$C$14),1,0) | AC30: =IF($P30="","Jamais relancé",IF($P30<=3,"0-3 j",IF($P30<=7,"4-7 j",IF($P30<=15,"8-15 j","Plus de 15 j")))) | AD30: =IF($M30<=1000,"Moins de 1 k€",IF($M30<=5000,"1 à 5 k€",IF($M30<=15000,"5 à 15 k€","Plus de 15 k€")))
